#VRML_SIM R2023a utf8

EXTERNPROTO "https://raw.githubusercontent.com/cyberbotics/webots/R2023a/projects/objects/backgrounds/protos/TexturedBackground.proto"
EXTERNPROTO "https://raw.githubusercontent.com/cyberbotics/webots/R2023a/projects/objects/backgrounds/protos/TexturedBackgroundLight.proto"
EXTERNPROTO "https://raw.githubusercontent.com/cyberbotics/webots/R2023a/projects/objects/floors/protos/RectangleArena.proto"
EXTERNPROTO "https://raw.githubusercontent.com/cyberbotics/webots/R2023a/projects/objects/balls/protos/FifaSoccerBall.proto"

WorldInfo {
}
Viewpoint {
  orientation 0.44851934375653685 0.2631375729078924 -0.8541598304769132 2.2125016052490936
  position 0.6898727830577525 1.1007054676289927 1.0940769033792994
}
TexturedBackground {
}
TexturedBackgroundLight {
}
RectangleArena {
  rotation 0 1 0 0
  floorSize 2 2
  floorTileSize 1 1
}
FifaSoccerBall {
  translation -0.7773852962728568 0.1657517169668462 0.11182507199999997
  rotation 0.8754033415601365 0.48017301363286574 0.05570338018539588 1.901670140148845
}
Robot {
  translation 0.215155 0.492334 0.0397225
  rotation 4.019143842870302e-08 1.9624842990504044e-08 -0.999999999999999 2.6143956029088993
  children [
    DEF Body Shape {
      appearance PBRAppearance {
        baseColor 0.1 0.7 1
        metalness 0
      }
      geometry Box {
        size 0.1 0.2 0.05
      }
    }
    HingeJoint {
      jointParameters HingeJointParameters {
        position -27.456032979843837
        anchor 0.06 0.05 -1.49514e-06
      }
      device [
        RotationalMotor {
          name "wheel1"
        }
      ]
      endPoint Solid {
        translation 0.059999999999999984 0.04999999999628113 -1.4951367173347495e-06
        rotation -0.6760405984121789 0.29314681371336415 -0.6760429386571574 2.57127918380265
        children [
          DEF Wheel Shape {
            appearance PBRAppearance {
              baseColor 1 0.3 0.2
              metalness 0
            }
            geometry Cylinder {
              height 0.02
              radius 0.04
            }
          }
        ]
        boundingObject USE Wheel
        physics DEF Physics_wh Physics {
        }
      }
    }
    HingeJoint {
      jointParameters HingeJointParameters {
        position -40.25596577919403
        anchor -0.06 0.05 -1.49514e-06
      }
      device [
        RotationalMotor {
          name "wheel2"
        }
      ]
      endPoint Solid {
        translation -0.05999999999999997 0.05000000267977251 -1.4991884873330682e-06
        rotation -0.6916142365436015 0.20817317810194572 -0.6916167115745154 2.7311102994828804
        children [
          DEF Wheel Shape {
            appearance PBRAppearance {
              baseColor 1 0.3 0.2
              metalness 0
            }
            geometry Cylinder {
              height 0.02
              radius 0.04
            }
          }
        ]
        name "solid(3)"
        boundingObject USE Wheel
        physics DEF Physics_wh Physics {
        }
      }
    }
    HingeJoint {
      jointParameters HingeJointParameters {
        position -40.25596618987755
        anchor -0.06 -0.05 -1.49514e-06
      }
      device [
        RotationalMotor {
          name "wheel4"
        }
      ]
      endPoint Solid {
        translation -0.059999999999999984 -0.049999997319987464 -1.4991883283881842e-06
        rotation -0.6916143774411909 0.20817294523742358 -0.6916166407684321 2.731110623716141
        children [
          DEF Wheel Shape {
            appearance PBRAppearance {
              baseColor 1 0.3 0.2
              metalness 0
            }
            geometry Cylinder {
              height 0.02
              radius 0.04
            }
          }
        ]
        name "solid(1)"
        boundingObject USE Wheel
        physics DEF Physics_wh Physics {
        }
      }
    }
    HingeJoint {
      jointParameters HingeJointParameters {
        position -27.45603430763727
        anchor 0.06 -0.05 -1.49514e-06
      }
      device [
        RotationalMotor {
          name "wheel3"
        }
      ]
      endPoint Solid {
        translation 0.05999999999999997 -0.049999996455794775 -1.4984581378642658e-06
        rotation -0.6760407160421159 0.2931462711663264 -0.6760430562874986 2.57128018302547
        children [
          DEF Wheel Shape {
            appearance PBRAppearance {
              baseColor 1 0.3 0.2
              metalness 0
            }
            geometry Cylinder {
              height 0.02
              radius 0.04
            }
          }
        ]
        name "solid(2)"
        boundingObject USE Wheel
        physics DEF Physics_wh Physics {
        }
      }
    }
    DistanceSensor {
      translation -0.03 0.1 0
      rotation 0 0 1 1.8544996938995748
      scale 0.05 0.05 0.05
      children [
        DEF sensor Shape {
          appearance PBRAppearance {
            baseColor 0.3 0 1
            metalness 0
          }
          geometry Box {
            size 0.1 0.1 0.1
          }
        }
      ]
      name "ds_left"
      boundingObject USE sensor
      physics Physics {
      }
    }
    DistanceSensor {
      translation 0.03 0.1 0
      rotation 0 0 1 1.2
      scale 0.05 0.05 0.05
      children [
        DEF sensor Shape {
          appearance PBRAppearance {
            baseColor 0.3 0 1
            metalness 0
          }
          geometry Box {
            size 0.1 0.1 0.1
          }
        }
      ]
      name "ds_right"
      boundingObject USE sensor
      physics Physics {
      }
    }
  ]
  boundingObject USE Body
  physics Physics {
  }
  controller "Python_controller"
}
