#VRML_SIM R2023a utf8

EXTERNPROTO "https://raw.githubusercontent.com/cyberbotics/webots/R2023a/projects/objects/backgrounds/protos/TexturedBackground.proto"
EXTERNPROTO "https://raw.githubusercontent.com/cyberbotics/webots/R2023a/projects/objects/backgrounds/protos/TexturedBackgroundLight.proto"
EXTERNPROTO "https://raw.githubusercontent.com/cyberbotics/webots/R2023a/projects/objects/floors/protos/RectangleArena.proto"
EXTERNPROTO "https://raw.githubusercontent.com/cyberbotics/webots/R2023a/projects/objects/balls/protos/FifaSoccerBall.proto"

WorldInfo {
}
Viewpoint {
  orientation 0.5954811789507908 0.14131916214281504 -0.7908419942862348 2.770540283604113
  position 0.4032217167288944 -0.12234264508158832 1.7528323932878285
}
TexturedBackground {
}
TexturedBackgroundLight {
}
RectangleArena {
  rotation 0 1 0 0
  floorSize 2 2
  floorTileSize 1 1
}
FifaSoccerBall {
  hidden linearVelocity_0 -0.017363973967616107 -0.011232198351118597 2.083933309648761e-16
  hidden angularVelocity_0 0.09984176312105418 -0.15434643526769873 -0.13894167356112314
  translation -0.1904090506598068 0.7907589563060422 0.11182507199999997
  rotation 0.3884131706680434 -0.6454657260762217 -0.6576543205305455 2.0321101067397267
}
Robot {
  translation -4.080441959072544e-09 -0.5555199263315881 0.03972247353335547
  rotation 0.074863897293624 -0.3176892210383873 -0.9452348680185431 7.713385628014745e-08
  children [
    DEF Body Shape {
      appearance PBRAppearance {
        baseColor 0.1 0.7 1
        metalness 0
      }
      geometry Box {
        size 0.1 0.2 0.05
      }
    }
    HingeJoint {
      jointParameters HingeJointParameters {
        position 13.88799989656821
        anchor 0.06 0.05 -1.49514e-06
      }
      device [
        RotationalMotor {
          name "wheel1"
        }
      ]
      endPoint Solid {
        translation 0.059999999999999984 0.05000000000484104 -1.4951410817795934e-06
        rotation 0.5230915980507779 0.6728658600968457 0.5230934088332748 1.9570316955781177
        children [
          DEF Wheel Shape {
            appearance PBRAppearance {
              baseColor 1 0.3 0.2
              metalness 0
            }
            geometry Cylinder {
              height 0.02
              radius 0.04
            }
          }
        ]
        boundingObject USE Wheel
        physics DEF Physics_wh Physics {
        }
        linearVelocity 2.2270261563327433e-09 -0.039999998571638336 -3.6821874544103596e-09
        angularVelocity 0.999999976348614 2.8770386982865225e-08 2.337033379649584e-08
      }
    }
    HingeJoint {
      jointParameters HingeJointParameters {
        position 13.887999896264176
        anchor -0.06 0.05 -1.49514e-06
      }
      device [
        RotationalMotor {
          name "wheel2"
        }
      ]
      endPoint Solid {
        translation -0.05999999999999997 0.04999999529492661 -1.4939426217148892e-06
        rotation 0.5230915535454431 0.6728658817417503 0.5230934254961649 1.9570317741012186
        children [
          DEF Wheel Shape {
            appearance PBRAppearance {
              baseColor 1 0.3 0.2
              metalness 0
            }
            geometry Cylinder {
              height 0.02
              radius 0.04
            }
          }
        ]
        name "solid(3)"
        boundingObject USE Wheel
        physics DEF Physics_wh Physics {
        }
        linearVelocity 2.2270497610128312e-09 -0.039999998358418894 3.671233129343642e-09
        angularVelocity 0.9999999763314971 2.8768624382518537e-08 2.3373410765317408e-08
      }
    }
    HingeJoint {
      jointParameters HingeJointParameters {
        position 13.888000090453867
        anchor -0.06 -0.05 -1.49514e-06
      }
      device [
        RotationalMotor {
          name "wheel4"
        }
      ]
      endPoint Solid {
        translation -0.059999999999999984 -0.05000000470514507 -1.4939429035663206e-06
        rotation 0.5230916805874489 0.6728658086923976 0.523093392419484 1.9570315911170397
        children [
          DEF Wheel Shape {
            appearance PBRAppearance {
              baseColor 1 0.3 0.2
              metalness 0
            }
            geometry Cylinder {
              height 0.02
              radius 0.04
            }
          }
        ]
        name "solid(1)"
        boundingObject USE Wheel
        physics DEF Physics_wh Physics {
        }
        linearVelocity 7.721070304965323e-11 -0.03999999835818213 5.9861387875715346e-09
        angularVelocity 0.9999999763314764 2.883870628325949e-08 2.3412808030456808e-08
      }
    }
    HingeJoint {
      jointParameters HingeJointParameters {
        position 13.888000091075073
        anchor 0.06 -0.05 -1.49514e-06
      }
      device [
        RotationalMotor {
          name "wheel3"
        }
      ]
      endPoint Solid {
        translation 0.05999999999999997 -0.05000000470514503 -1.4939429035782553e-06
        rotation 0.5230916088641395 0.6728658432839845 0.5230934196466805 1.9570317187243589
        children [
          DEF Wheel Shape {
            appearance PBRAppearance {
              baseColor 1 0.3 0.2
              metalness 0
            }
            geometry Cylinder {
              height 0.02
              radius 0.04
            }
          }
        ]
        name "solid(2)"
        boundingObject USE Wheel
        physics DEF Physics_wh Physics {
        }
        linearVelocity 7.724990899418423e-11 -0.04000000093360966 -5.9744610630062885e-09
        angularVelocity 0.999999976536855 2.88358604082083e-08 2.3417786112718522e-08
      }
    }
    DistanceSensor {
      translation -0.03 0.1 0
      rotation 0 0 1 1.8544996938995748
      scale 0.05 0.05 0.05
      children [
        Shape {
          appearance PBRAppearance {
            baseColor 0.3 0 1
            metalness 0
          }
          geometry Box {
            size 0.1 0.1 0.1
          }
        }
      ]
      name "ds_left"
    }
    DistanceSensor {
      translation 0.03 0.1 0
      rotation 0 0 -1 -1.2
      scale 0.05 0.05 0.05
      children [
        Shape {
          appearance PBRAppearance {
            baseColor 0.3 0 1
            metalness 0
          }
          geometry Box {
            size 0.1 0.1 0.1
          }
        }
      ]
      name "df_right"
    }
  ]
  boundingObject USE Body
  physics Physics {
  }
  controller "my_ob_avoid"
  linearVelocity 1.152286446623261e-09 -0.039999998093773415 3.519879044233677e-09
  angularVelocity -2.3612800552976457e-08 1.0166509133687755e-07 -2.9017538163007034e-09
}
