#VRML_SIM R2023a utf8

EXTERNPROTO "https://raw.githubusercontent.com/cyberbotics/webots/R2023a/projects/objects/backgrounds/protos/TexturedBackground.proto"
EXTERNPROTO "https://raw.githubusercontent.com/cyberbotics/webots/R2023a/projects/objects/backgrounds/protos/TexturedBackgroundLight.proto"
EXTERNPROTO "https://raw.githubusercontent.com/cyberbotics/webots/R2023a/projects/objects/floors/protos/RectangleArena.proto"
EXTERNPROTO "https://raw.githubusercontent.com/cyberbotics/webots/R2023a/projects/objects/obstacles/protos/OilBarrel.proto"

WorldInfo {
}
Viewpoint {
  orientation 0.4020939416958684 0.00441140704789192 -0.9155877901869035 3.1214963129557383
  position 4.017096680823083 0.12444166130217166 4.457407476876239
}
TexturedBackground {
}
TexturedBackgroundLight {
}
RectangleArena {
  rotation 0 1 0 0
  floorSize 2 2
  floorTileSize 1 1
}
Robot {
  translation -0.30710035775961314 -0.8945618142575283 0.03972087398426735
  rotation 4.049699630020029e-05 3.208335158752276e-05 0.9999999986653259 1.3377445652061912
  children [
    DEF Body Shape {
      appearance PBRAppearance {
        baseColor 0.1 0.7 1
        metalness 0
      }
      geometry Box {
        size 0.1 0.2 0.05
      }
    }
    HingeJoint {
      jointParameters HingeJointParameters {
        position 693.4766280467687
        anchor 0.06 0.05 -1.49514e-06
      }
      device [
        RotationalMotor {
          name "wheel1"
        }
      ]
      endPoint Solid {
        translation 0.059999999999999984 0.05000000000350977 -1.495136494663863e-06
        rotation 0.6762750813875732 0.2920631133614505 0.6762774224442569 2.5732756456521275
        children [
          DEF Wheel Shape {
            appearance PBRAppearance {
              baseColor 1 0.3 0.2
              metalness 0
            }
            geometry Cylinder {
              height 0.02
              radius 0.04
            }
          }
        ]
        boundingObject USE Wheel
        physics DEF Physics_wh Physics {
        }
        linearVelocity 0.0389186433201145 -0.0092379128980309 -3.0534996356155464e-09
        angularVelocity 0.23094779379707472 0.9729661337706925 -2.0314413613906787e-08
      }
    }
    HingeJoint {
      jointParameters HingeJointParameters {
        position 1460.6709943799428
        anchor -0.06 0.05 -1.49514e-06
      }
      device [
        RotationalMotor {
          name "wheel2"
        }
      ]
      endPoint Solid {
        translation -0.05999999999999997 0.04999999918043392 -1.4999253674672744e-06
        rotation 0.7058317955469087 0.05999489184994461 0.7058343214571959 3.021746950861227
        children [
          DEF Wheel Shape {
            appearance PBRAppearance {
              baseColor 1 0.3 0.2
              metalness 0
            }
            geometry Cylinder {
              height 0.02
              radius 0.04
            }
          }
        ]
        name "solid(3)"
        boundingObject USE Wheel
        physics DEF Physics_wh Physics {
        }
        linearVelocity 0.038918643636280774 -0.009237913250169334 3.0570241961213922e-09
        angularVelocity 0.23094779374828803 0.972966133814126 -2.034770364712333e-08
      }
    }
    HingeJoint {
      jointParameters HingeJointParameters {
        position 862.9109966713077
        anchor -0.06 -0.05 -1.49514e-06
      }
      device [
        RotationalMotor {
          name "wheel4"
        }
      ]
      endPoint Solid {
        translation -0.059999999999999984 -0.050000004154587704 -1.49765213675222e-06
        rotation -0.6568082268398058 -0.3704093448994948 -0.6568103762629495 3.8510703711715477
        children [
          DEF Wheel Shape {
            appearance PBRAppearance {
              baseColor 1 0.3 0.2
              metalness 0
            }
            geometry Cylinder {
              height 0.02
              radius 0.04
            }
          }
        ]
        name "solid(1)"
        boundingObject USE Wheel
        physics DEF Physics_wh Physics {
        }
        linearVelocity 0.03891864703853297 -0.009237910524241858 9.347042382343416e-10
        angularVelocity 0.23094779380665992 0.972966134019891 -2.0328209054347112e-08
      }
    }
    HingeJoint {
      jointParameters HingeJointParameters {
        position 709.7965132837219
        anchor 0.06 -0.05 -1.49514e-06
      }
      device [
        RotationalMotor {
          name "wheel3"
        }
      ]
      endPoint Solid {
        translation 0.05999999999999997 -0.04999999901929592 -1.4903850395332009e-06
        rotation 0.10101820227188896 -0.9897426811896474 0.10101855196588226 4.702075413916046
        children [
          DEF Wheel Shape {
            appearance PBRAppearance {
              baseColor 1 0.3 0.2
              metalness 0
            }
            geometry Cylinder {
              height 0.02
              radius 0.04
            }
          }
        ]
        name "solid(2)"
        boundingObject USE Wheel
        physics DEF Physics_wh Physics {
        }
        linearVelocity 0.03891864742943748 -0.009237910338680506 -9.38765757373176e-10
        angularVelocity 0.23094779392953033 0.9729661340185457 -2.048411023939863e-08
      }
    }
    TouchSensor {
      translation 0.050000000000004374 -0.10000000000402297 -6.278399992259986e-08
      rotation 1.1268274894698925e-16 3.3377119454778384e-16 -0.9999999999999999 1.5707953071795857
      children [
        Shape {
          appearance PBRAppearance {
          }
          geometry Box {
            size 0.01 0.04 0.01
          }
        }
      ]
      name "touch sensor 1"
      boundingObject Box {
        size 0.01 0.04 0.01
      }
      physics Physics {
      }
      linearVelocity 0.03891864457596314 -0.009237906395824697 -1.0813083122038908e-09
      angularVelocity -6.315761221881072e-08 5.3292927365433215e-09 5.0322751596253236e-08
    }
    TouchSensor {
      translation -0.049999999999995604 -0.1000000000040229 -6.278399986708871e-08
      rotation -2.4089489319683147e-16 1.5058745857119283e-16 -0.9999999999999999 1.5707953071795857
      children [
        Shape {
          appearance PBRAppearance {
          }
          geometry Box {
            size 0.01 0.04 0.01
          }
        }
      ]
      name "touch sensor 2"
      boundingObject Box {
        size 0.01 0.04 0.01
      }
      physics Physics {
      }
      linearVelocity 0.03891864947219638 -0.009237907558017322 5.18679219518002e-09
      angularVelocity -6.315762030470087e-08 5.32928851554457e-09 5.0322751595887755e-08
    }
  ]
  boundingObject USE Body
  physics Physics {
  }
  controller "PY_script_1"
  linearVelocity 0.038918645861920675 -0.009237911872749518 1.1126515314534894e-09
  angularVelocity -6.315761483642772e-08 5.3292820136490706e-09 5.032274951470999e-08
}
OilBarrel {
  translation 0 0 0.1
  height 0.2
  radius 0.09
}
OilBarrel {
  translation 0.25 0 0.1
  name "oil barrel(1)"
  height 0.2
  radius 0.09
}
OilBarrel {
  translation 0.52 -0.87 0.1
  name "oil barrel(2)"
  height 0.2
  radius 0.09
}
