#VRML_SIM R2023a utf8

EXTERNPROTO "https://raw.githubusercontent.com/cyberbotics/webots/R2023a/projects/objects/backgrounds/protos/TexturedBackground.proto"
EXTERNPROTO "https://raw.githubusercontent.com/cyberbotics/webots/R2023a/projects/objects/backgrounds/protos/TexturedBackgroundLight.proto"
EXTERNPROTO "https://raw.githubusercontent.com/cyberbotics/webots/R2023a/projects/objects/floors/protos/RectangleArena.proto"
EXTERNPROTO "https://raw.githubusercontent.com/cyberbotics/webots/R2023a/projects/objects/obstacles/protos/OilBarrel.proto"
EXTERNPROTO "https://raw.githubusercontent.com/cyberbotics/webots/R2023a/projects/appearances/protos/Parquetry.proto"

WorldInfo {
}
Viewpoint {
  orientation -0.04099902377717157 -0.9892715159071916 0.14021750198889563 5.708484740916974
  position -1.9874541724975043 0.008076029501382254 1.442476879035983
}
TexturedBackground {
}
TexturedBackgroundLight {
}
RectangleArena {
  rotation 0 1 0 0
  floorSize 2 2
  floorTileSize 1 1
  floorAppearance Parquetry {
  }
}
Robot {
  translation 0.0010366521342204751 0.17479342117076901 0.03975818593373013
  rotation 1.618523020484811e-05 -2.7273199455312856e-05 -0.9999999994971055 2.6611424188860524
  children [
    DEF Body Shape {
      appearance PBRAppearance {
        baseColor 0.1 0.7 1
        metalness 0
      }
      geometry Box {
        size 0.1 0.2 0.05
      }
    }
    HingeJoint {
      jointParameters HingeJointParameters {
        position 29514.886790786728
        anchor 0.06 0.05 -1.49514e-06
      }
      device [
        RotationalMotor {
          name "wheel1"
        }
      ]
      endPoint Solid {
        translation 0.05999999999970629 0.04999834658777208 2.025422357795739e-06
        rotation -0.7007864455365381 -0.13339158675048476 -0.7007888714416437 3.406809281713328
        children [
          DEF Wheel Shape {
            appearance PBRAppearance {
              baseColor 1 0.3 0.2
              metalness 0
            }
            geometry Cylinder {
              height 0.01
              radius 0.04
            }
          }
        ]
        boundingObject USE Wheel
        physics DEF Physics_wh Physics {
        }
        linearVelocity 0.04420152020009851 -0.01349663392349533 1.2894636676912167e-06
        angularVelocity 0.8900022784984446 0.45597494501760627 0.4422831809395985
      }
    }
    HingeJoint {
      jointParameters HingeJointParameters {
        position 38003.46370168817
        anchor -0.06 0.05 -1.49514e-06
      }
      device [
        RotationalMotor {
          name "wheel2"
        }
      ]
      endPoint Solid {
        translation -0.05999999942556988 0.0500007845854534 2.1312057453102953e-06
        rotation 0.7005659044945715 0.13568829885143405 0.7005684113735838 2.871864316579798
        children [
          DEF Wheel Shape {
            appearance PBRAppearance {
              baseColor 1 0.3 0.2
              metalness 0
            }
            geometry Cylinder {
              height 0.01
              radius 0.04
            }
          }
        ]
        name "solid(3)"
        boundingObject USE Wheel
        physics DEF Physics_wh Physics {
        }
        linearVelocity 0.020027991921952898 0.03364316294701125 1.4093374227634315e-07
        angularVelocity -0.8900792568041158 -0.4558927795440739 0.44224643345557796
      }
    }
    HingeJoint {
      jointParameters HingeJointParameters {
        position 37405.69883007865
        anchor -0.06 -0.05 -1.49514e-06
      }
      device [
        RotationalMotor {
          name "wheel4"
        }
      ]
      endPoint Solid {
        translation -0.05999999980825865 -0.04999913473560722 2.425499734992233e-06
        rotation 0.6305696712166452 0.45250544421394645 0.6305717347760451 2.291724109977789
        children [
          DEF Wheel Shape {
            appearance PBRAppearance {
              baseColor 1 0.3 0.2
              metalness 0
            }
            geometry Cylinder {
              height 0.01
              radius 0.04
            }
          }
        ]
        name "solid(1)"
        boundingObject USE Wheel
        physics DEF Physics_wh Physics {
        }
        linearVelocity -0.019249093876846937 0.013499661901866546 -1.1094759305661173e-06
        angularVelocity -0.8900798943695959 -0.4558931636457469 0.44224611457209373
      }
    }
    HingeJoint {
      jointParameters HingeJointParameters {
        position 29531.201516451554
        anchor 0.06 -0.05 -1.49514e-06
      }
      device [
        RotationalMotor {
          name "wheel3"
        }
      ]
      endPoint Solid {
        translation 0.05999999970784975 -0.0500016164201543 1.9975374318760623e-06
        rotation -0.11427713390245735 -0.9868542865790898 -0.11427752940764668 4.699153022358977
        children [
          DEF Wheel Shape {
            appearance PBRAppearance {
              baseColor 1 0.3 0.2
              metalness 0
            }
            geometry Cylinder {
              height 0.01
              radius 0.04
            }
          }
        ]
        name "solid(2)"
        boundingObject USE Wheel
        physics DEF Physics_wh Physics {
        }
        linearVelocity 0.004924410036300388 -0.03364032891997482 -2.588075582712496e-07
        angularVelocity 0.8900015605611726 0.4559745227897441 0.44228350462157484
      }
    }
    TouchSensor {
      translation 0.05002282965530093 -0.10004470392855955 -4.021656919706018e-07
      rotation 1.9338224183214304e-09 1.6437957163399388e-09 -1 1.5707953072882768
      children [
        Shape {
          appearance PBRAppearance {
          }
          geometry Box {
            size 0.01 0.04 0.01
          }
        }
      ]
      name "touch sensor 1"
      boundingObject Box {
        size 0.01 0.04 0.01
      }
      physics Physics {
      }
      linearVelocity -0.016728435983375207 -0.03977879397822415 1.0261204949029926e-07
      angularVelocity -3.8731631006426824e-05 4.073389620979656e-05 0.44119965564536684
    }
    TouchSensor {
      translation -0.05002966873645877 -0.1000413055918046 -4.3393164317340194e-07
      rotation 1.8610930315080339e-09 1.896708212915234e-09 -1 1.5707953072863623
      children [
        Shape {
          appearance PBRAppearance {
          }
          geometry Box {
            size 0.01 0.04 0.01
          }
        }
      ]
      name "touch sensor 2"
      boundingObject Box {
        size 0.01 0.04 0.01
      }
      physics Physics {
      }
      linearVelocity -0.03687203701182117 -0.0005003129675453923 -5.317508325524214e-06
      angularVelocity -3.873163103105464e-05 4.073389624288859e-05 0.44119965564506575
    }
  ]
  boundingObject USE Body
  physics Physics {
  }
  controller "PY_script_1"
  linearVelocity 0.012474521859102881 2.127783028853857e-06 -1.0300266032759673e-06
  angularVelocity -3.873163102988194e-05 4.073389624743677e-05 0.4411996556445315
}
OilBarrel {
  translation 0 -0.75 0.1
  height 0.2
  radius 0.09
}
OilBarrel {
  translation -0.43 0.89 0.1
  name "oil barrel(3)"
  height 0.2
  radius 0.09
}
OilBarrel {
  translation 0.25 0 0.1
  name "oil barrel(1)"
  height 0.2
  radius 0.09
}
OilBarrel {
  translation -0.09 0.42 0.1
  name "oil barrel(5)"
  height 0.2
  radius 0.09
}
OilBarrel {
  translation -0.69 -0.51 0.1
  name "oil barrel(2)"
  height 0.2
  radius 0.09
}
OilBarrel {
  translation 0.52 -0.87 0.1
  name "oil barrel(4)"
  height 0.2
  radius 0.09
}
