#VRML_SIM R2023a utf8

EXTERNPROTO "https://raw.githubusercontent.com/cyberbotics/webots/R2023a/projects/objects/backgrounds/protos/TexturedBackground.proto"
EXTERNPROTO "https://raw.githubusercontent.com/cyberbotics/webots/R2023a/projects/objects/backgrounds/protos/TexturedBackgroundLight.proto"
EXTERNPROTO "https://raw.githubusercontent.com/cyberbotics/webots/R2023a/projects/objects/floors/protos/RectangleArena.proto"
EXTERNPROTO "https://raw.githubusercontent.com/cyberbotics/webots/R2023a/projects/objects/obstacles/protos/OilBarrel.proto"
EXTERNPROTO "https://raw.githubusercontent.com/cyberbotics/webots/R2023a/projects/appearances/protos/Parquetry.proto"

WorldInfo {
}
Viewpoint {
  orientation 0.042602005935659826 0.9898509201488601 -0.1355736883422183 0.6147224446961351
  position -10.933892512501474 0.502029041481433 8.285264126664426
}
TexturedBackground {
}
TexturedBackgroundLight {
}
RectangleArena {
  rotation 0 1 0 0
  floorSize 2 2
  floorTileSize 1 1
  floorAppearance Parquetry {
  }
}
Robot {
  translation -0.895247456180932 0.616557203749716 0.039762177633870494
  rotation -0.0018933902073383954 0.001904592361084377 -0.9999963937942282 1.5708003857505757
  children [
    DEF Body Shape {
      appearance PBRAppearance {
        baseColor 0.1 0.7 1
        metalness 0
      }
      geometry Box {
        size 0.1 0.2 0.05
      }
    }
    HingeJoint {
      jointParameters HingeJointParameters {
        position 19123.369771308753
        anchor 0.06 0.05 -1.49514e-06
      }
      device [
        RotationalMotor {
          name "wheel1"
        }
      ]
      endPoint Solid {
        translation 0.05999999999970629 0.049996241484262745 -4.942949753612326e-07
        rotation -0.6960689284608812 0.17599073610738444 -0.6960713380363408 2.793180233682115
        children [
          DEF Wheel Shape {
            appearance PBRAppearance {
              baseColor 1 0.3 0.2
              metalness 0
            }
            geometry Cylinder {
              height 0.01
              radius 0.04
            }
          }
        ]
        boundingObject USE Wheel
        physics DEF Physics_wh Physics {
        }
        linearVelocity 1.239568757920467e-05 -1.7223652121988744e-05 5.671134936622001e-06
        angularVelocity 0.000428742404241756 -9.999902890182168 -2.0869241652342023e-05
      }
    }
    HingeJoint {
      jointParameters HingeJointParameters {
        position 24644.96298904
        anchor -0.06 0.05 -1.49514e-06
      }
      device [
        RotationalMotor {
          name "wheel2"
        }
      ]
      endPoint Solid {
        translation -0.05999999942556988 0.05000228015503114 1.4317783166279253e-06
        rotation 0.6749899074541456 0.29794964169900773 0.6749923228055835 2.5624452682835335
        children [
          DEF Wheel Shape {
            appearance PBRAppearance {
              baseColor 1 0.3 0.2
              metalness 0
            }
            geometry Cylinder {
              height 0.01
              radius 0.04
            }
          }
        ]
        name "solid(3)"
        boundingObject USE Wheel
        physics DEF Physics_wh Physics {
        }
        linearVelocity 3.0688785064681125e-05 -1.722354230052098e-05 -9.671019729282174e-06
        angularVelocity 0.00042874237115306485 -9.999902890596337 -2.0869261025136733e-05
      }
    }
    HingeJoint {
      jointParameters HingeJointParameters {
        position 24047.200404530246
        anchor -0.06 -0.05 -1.49514e-06
      }
      device [
        RotationalMotor {
          name "wheel4"
        }
      ]
      endPoint Solid {
        translation -0.05999999980825865 -0.049997526704762554 1.667597590984171e-06
        rotation 0.5527105155453862 0.6237148166931441 0.55271232430894 2.02624638307394
        children [
          DEF Wheel Shape {
            appearance PBRAppearance {
              baseColor 1 0.3 0.2
              metalness 0
            }
            geometry Cylinder {
              height 0.01
              radius 0.04
            }
          }
        ]
        name "solid(1)"
        boundingObject USE Wheel
        physics DEF Physics_wh Physics {
        }
        linearVelocity 3.312955248435991e-05 -1.6927834813564884e-05 -2.433509848791095e-06
        angularVelocity 0.0004287346500375419 -9.99990287114448 -2.086532315815178e-05
      }
    }
    HingeJoint {
      jointParameters HingeJointParameters {
        position 19139.686879857003
        anchor 0.06 -0.05 -1.49514e-06
      }
      device [
        RotationalMotor {
          name "wheel3"
        }
      ]
      endPoint Solid {
        translation 0.05999999970784975 -0.050003715763317975 -4.927864081236577e-07
        rotation -0.4645382932224569 -0.7539276187921503 -0.46453990114129545 4.433609424875838
        children [
          DEF Wheel Shape {
            appearance PBRAppearance {
              baseColor 1 0.3 0.2
              metalness 0
            }
            geometry Cylinder {
              height 0.01
              radius 0.04
            }
          }
        ]
        name "solid(2)"
        boundingObject USE Wheel
        physics DEF Physics_wh Physics {
        }
        linearVelocity 1.2439009761324968e-05 -1.6927972519555625e-05 1.462499589165416e-05
        angularVelocity 0.0004287346839644483 -9.999902872879446 -2.086532056962481e-05
      }
    }
    TouchSensor {
      translation 0.049999980220549856 -0.09999051050884034 -3.325385525485003e-07
      rotation -1.9338194670307497e-09 -1.6437971070233862e-09 1 -1.5707953072882948
      children [
        Shape {
          appearance PBRAppearance {
          }
          geometry Box {
            size 0.01 0.04 0.01
          }
        }
      ]
      name "touch sensor 1"
      boundingObject Box {
        size 0.01 0.04 0.01
      }
      physics Physics {
      }
      linearVelocity -3.591855453066727e-07 -1.6039930838894486e-05 -1.5142811951029952e-05
      angularVelocity 0.000419609714881161 9.593420644246223e-05 -8.771293942983563e-06
    }
    TouchSensor {
      translation -0.05000001970649537 -0.09999051219844868 -3.6867363207432335e-07
      rotation -1.8610930539647513e-09 -1.8967081965400772e-09 1 -1.570795307286419
      children [
        Shape {
          appearance PBRAppearance {
          }
          geometry Box {
            size 0.01 0.04 0.01
          }
        }
      ]
      name "touch sensor 2"
      boundingObject Box {
        size 0.01 0.04 0.01
      }
      physics Physics {
      }
      linearVelocity 4.841150147427696e-07 -1.6042664488270794e-05 2.6368952322330934e-05
      angularVelocity 0.0004196069450778629 9.593196988726576e-05 -8.771279797167602e-06
    }
  ]
  boundingObject USE Body
  physics Physics {
  }
  controller "PY_script_1"
  linearVelocity 2.864479904474137e-08 -1.697061500562213e-05 -4.060024260127193e-06
  angularVelocity 0.0004196076084299024 9.593278641886383e-05 -8.770369124873687e-06
}
OilBarrel {
  translation 0 -0.75 0.1
  height 0.2
  radius 0.09
}
OilBarrel {
  translation 0.25 0 0.1
  name "oil barrel(1)"
  height 0.2
  radius 0.09
}
OilBarrel {
  translation 0.52 -0.87 0.1
  name "oil barrel(2)"
  height 0.2
  radius 0.09
}
