#VRML_SIM R2023a utf8

EXTERNPROTO "https://raw.githubusercontent.com/cyberbotics/webots/R2023a/projects/objects/backgrounds/protos/TexturedBackground.proto"
EXTERNPROTO "https://raw.githubusercontent.com/cyberbotics/webots/R2023a/projects/objects/backgrounds/protos/TexturedBackgroundLight.proto"
EXTERNPROTO "https://raw.githubusercontent.com/cyberbotics/webots/R2023a/projects/objects/floors/protos/RectangleArena.proto"
EXTERNPROTO "https://raw.githubusercontent.com/cyberbotics/webots/R2023a/projects/objects/obstacles/protos/OilBarrel.proto"
EXTERNPROTO "https://raw.githubusercontent.com/cyberbotics/webots/R2023a/projects/appearances/protos/Parquetry.proto"

WorldInfo {
}
Viewpoint {
  orientation 0.042602005935659826 0.9898509201488601 -0.1355736883422183 0.6147224446961351
  position -4.244997843745214 -0.07472964238096949 3.6042673500061353
}
TexturedBackground {
}
TexturedBackgroundLight {
}
RectangleArena {
  rotation 0 1 0 0
  floorSize 2 2
  floorTileSize 1 1
  floorAppearance Parquetry {
  }
}
Robot {
  translation -0.784834217242803 0.7026449114044283 0.03976099703705486
  rotation -6.681346220943912e-05 -2.931364722674731e-06 0.9999999977636841 -1.315417127008315
  children [
    DEF Body Shape {
      appearance PBRAppearance {
        baseColor 0.1 0.7 1
        metalness 0
      }
      geometry Box {
        size 0.1 0.2 0.05
      }
    }
    HingeJoint {
      jointParameters HingeJointParameters {
        position 18028.010902758797
        anchor 0.06 0.05 -1.49514e-06
      }
      device [
        RotationalMotor {
          name "wheel1"
        }
      ]
      endPoint Solid {
        translation 0.05999999999970629 0.05000271897252214 1.2861042780937391e-06
        rotation -0.57374774119404 -0.5844867662013051 -0.5737497273291534 4.199458854987439
        children [
          DEF Wheel Shape {
            appearance PBRAppearance {
              baseColor 1 0.3 0.2
              metalness 0
            }
            geometry Cylinder {
              height 0.01
              radius 0.04
            }
          }
        ]
        boundingObject USE Wheel
        physics DEF Physics_wh Physics {
        }
        linearVelocity -0.038703760194837115 -0.010104459169654554 1.713475744697566e-08
        angularVelocity 0.2526336570222172 -0.9675621267749902 -2.1557214403783112e-05
      }
    }
    HingeJoint {
      jointParameters HingeJointParameters {
        position 23549.604120598782
        anchor -0.06 0.05 -1.49514e-06
      }
      device [
        RotationalMotor {
          name "wheel2"
        }
      ]
      endPoint Solid {
        translation -0.05999999942556988 0.05000142823192444 -4.9194810122609524e-06
        rotation 0.11184899741174673 0.9874105093796031 0.11184939760544166 1.5834689756815614
        children [
          DEF Wheel Shape {
            appearance PBRAppearance {
              baseColor 1 0.3 0.2
              metalness 0
            }
            geometry Cylinder {
              height 0.01
              radius 0.04
            }
          }
        ]
        name "solid(3)"
        boundingObject USE Wheel
        physics DEF Physics_wh Physics {
        }
        linearVelocity -0.038701943920387796 -0.010103984928270365 -9.903233318731446e-09
        angularVelocity 0.25263361917333416 -0.9675619818727111 -2.1557238818949378e-05
      }
    }
    HingeJoint {
      jointParameters HingeJointParameters {
        position 22951.841538231507
        anchor -0.06 -0.05 -1.49514e-06
      }
      device [
        RotationalMotor {
          name "wheel4"
        }
      ]
      endPoint Solid {
        translation -0.05999999980825865 -0.04999846132375247 -5.203586279277071e-06
        rotation -0.2977541764546212 0.9070194708712291 -0.2977551508610817 1.6682364021673417
        children [
          DEF Wheel Shape {
            appearance PBRAppearance {
              baseColor 1 0.3 0.2
              metalness 0
            }
            geometry Cylinder {
              height 0.01
              radius 0.04
            }
          }
        ]
        name "solid(1)"
        boundingObject USE Wheel
        physics DEF Physics_wh Physics {
        }
        linearVelocity -0.03870108379261632 -0.010106201760480157 2.2594647027731005e-09
        angularVelocity 0.2526336442628939 -0.9675619528817598 -2.1577871344594158e-05
      }
    }
    HingeJoint {
      jointParameters HingeJointParameters {
        position 18044.328013536287
        anchor 0.06 -0.05 -1.49514e-06
      }
      device [
        RotationalMotor {
          name "wheel3"
        }
      ]
      endPoint Solid {
        translation 0.05999999970784975 -0.049997300733292845 1.2481370552720763e-06
        rotation 0.42588540103045136 -0.798274385587246 0.4258868752432229 4.488964982740425
        children [
          DEF Wheel Shape {
            appearance PBRAppearance {
              baseColor 1 0.3 0.2
              metalness 0
            }
            geometry Cylinder {
              height 0.01
              radius 0.04
            }
          }
        ]
        name "solid(2)"
        boundingObject USE Wheel
        physics DEF Physics_wh Physics {
        }
        linearVelocity -0.03870313918944037 -0.01010673843821143 -9.814560899228293e-09
        angularVelocity 0.2526336870750539 -0.9675621168614873 -2.157788237046073e-05
      }
    }
    TouchSensor {
      translation 0.05000000000575655 -0.10000000002488874 -3.138579699607513e-07
      rotation 1.6578264365424503e-16 -3.303290688610553e-16 0.9999999999999999 -1.5707953071795862
      children [
        Shape {
          appearance PBRAppearance {
          }
          geometry Box {
            size 0.01 0.04 0.01
          }
        }
      ]
      name "touch sensor 1"
      boundingObject Box {
        size 0.01 0.04 0.01
      }
      physics Physics {
      }
      linearVelocity -0.03870088608605747 -0.01010812167262769 -2.77557970827303e-06
      angularVelocity 2.1762960292281883e-05 5.64341793641602e-06 3.088860319840281e-05
    }
    TouchSensor {
      translation -0.04999999999862381 -0.10000000002433207 -3.13857780445681e-07
      rotation -8.596030599604485e-17 -3.422887636083311e-16 0.9999999999999999 -1.5707953071795862
      children [
        Shape {
          appearance PBRAppearance {
          }
          geometry Box {
            size 0.01 0.04 0.01
          }
        }
      ]
      name "touch sensor 2"
      boundingObject Box {
        size 0.01 0.04 0.01
      }
      physics Physics {
      }
      linearVelocity -0.03870387473783375 -0.010108902069870971 -5.273065143465144e-07
      angularVelocity 2.176296028981829e-05 5.643417942409614e-06 3.0888603198380906e-05
    }
  ]
  boundingObject USE Body
  physics Physics {
  }
  controller "PY_script_1"
  linearVelocity -0.038703160657766834 -0.010105523331069425 -1.6477236083691698e-06
  angularVelocity 2.176296029152473e-05 5.643417937731521e-06 3.0888603198490796e-05
}
OilBarrel {
  translation 0 -0.75 0.1
  height 0.2
  radius 0.09
}
OilBarrel {
  translation 0.25 0 0.1
  name "oil barrel(1)"
  height 0.2
  radius 0.09
}
OilBarrel {
  translation 0.52 -0.87 0.1
  name "oil barrel(2)"
  height 0.2
  radius 0.09
}
